[2025-09-04T21:40:41.496-0500] {taskinstance.py:1159} INFO - Dependencies all met for dep_context=non-requeueable deps ti=<TaskInstance: movie_sentiment_retrain.retrain_model manual__2025-09-05T02:40:26.496036+00:00 [queued]>
[2025-09-04T21:40:41.498-0500] {taskinstance.py:1159} INFO - Dependencies all met for dep_context=requeueable deps ti=<TaskInstance: movie_sentiment_retrain.retrain_model manual__2025-09-05T02:40:26.496036+00:00 [queued]>
[2025-09-04T21:40:41.499-0500] {taskinstance.py:1361} INFO - Starting attempt 1 of 2
[2025-09-04T21:40:41.504-0500] {taskinstance.py:1382} INFO - Executing <Task(PythonOperator): retrain_model> on 2025-09-05 02:40:26.496036+00:00
[2025-09-04T21:40:41.508-0500] {standard_task_runner.py:57} INFO - Started process 37757 to run task
[2025-09-04T21:40:41.511-0500] {standard_task_runner.py:84} INFO - Running: ['airflow', 'tasks', 'run', 'movie_sentiment_retrain', 'retrain_model', 'manual__2025-09-05T02:40:26.496036+00:00', '--job-id', '119', '--raw', '--subdir', 'DAGS_FOLDER/retrain_pipeline.py', '--cfg-path', '/var/folders/q5/0d_dg10s4m55__wc3fybh0280000gr/T/tmp2bdpy_hi']
[2025-09-04T21:40:41.512-0500] {standard_task_runner.py:85} INFO - Job 119: Subtask retrain_model
[2025-09-04T21:40:41.527-0500] {task_command.py:416} INFO - Running <TaskInstance: movie_sentiment_retrain.retrain_model manual__2025-09-05T02:40:26.496036+00:00 [running]> on host SebastianSamay.local
[2025-09-04T21:40:41.548-0500] {taskinstance.py:1662} INFO - Exporting env vars: AIRFLOW_CTX_DAG_OWNER='mlops-team' AIRFLOW_CTX_DAG_ID='movie_sentiment_retrain' AIRFLOW_CTX_TASK_ID='retrain_model' AIRFLOW_CTX_EXECUTION_DATE='2025-09-05T02:40:26.496036+00:00' AIRFLOW_CTX_TRY_NUMBER='1' AIRFLOW_CTX_DAG_RUN_ID='manual__2025-09-05T02:40:26.496036+00:00'
[2025-09-04T21:40:41.568-0500] {taskinstance.py:1937} ERROR - Task failed with exception
Traceback (most recent call last):
  File "/Users/sebatiancarvalho/Desktop/Repositorios/SCSProjects/movie-sentiment-mlops-V3/venv_mlops/lib/python3.9/site-packages/airflow/operators/python.py", line 192, in execute
    return_value = self.execute_callable()
  File "/Users/sebatiancarvalho/Desktop/Repositorios/SCSProjects/movie-sentiment-mlops-V3/venv_mlops/lib/python3.9/site-packages/airflow/operators/python.py", line 209, in execute_callable
    return self.python_callable(*self.op_args, **self.op_kwargs)
  File "/Users/sebatiancarvalho/Desktop/Repositorios/SCSProjects/movie-sentiment-mlops-V3/airflow/dags/retrain_pipeline.py", line 90, in retrain_model
    os.chdir(project_dir)
FileNotFoundError: [Errno 2] No such file or directory: '/home/airflow/movie-sentiment-mlops'
[2025-09-04T21:40:41.579-0500] {taskinstance.py:1400} INFO - Marking task as UP_FOR_RETRY. dag_id=movie_sentiment_retrain, task_id=retrain_model, execution_date=20250905T024026, start_date=20250905T024041, end_date=20250905T024041
[2025-09-04T21:40:41.582-0500] {standard_task_runner.py:104} ERROR - Failed to execute job 119 for task retrain_model ([Errno 2] No such file or directory: '/home/airflow/movie-sentiment-mlops'; 37757)
[2025-09-04T21:40:41.606-0500] {local_task_job_runner.py:228} INFO - Task exited with return code 1
[2025-09-04T21:40:41.615-0500] {taskinstance.py:2778} INFO - 0 downstream tasks scheduled from follow-on schedule check
