[2025-09-05T10:30:32.863-0500] {taskinstance.py:1159} INFO - Dependencies all met for dep_context=non-requeueable deps ti=<TaskInstance: movie_sentiment_retrain.check_drift manual__2025-09-05T15:25:18.269925+00:00 [queued]>
[2025-09-05T10:30:32.866-0500] {taskinstance.py:1159} INFO - Dependencies all met for dep_context=requeueable deps ti=<TaskInstance: movie_sentiment_retrain.check_drift manual__2025-09-05T15:25:18.269925+00:00 [queued]>
[2025-09-05T10:30:32.866-0500] {taskinstance.py:1361} INFO - Starting attempt 2 of 2
[2025-09-05T10:30:32.870-0500] {taskinstance.py:1382} INFO - Executing <Task(BranchPythonOperator): check_drift> on 2025-09-05 15:25:18.269925+00:00
[2025-09-05T10:30:32.874-0500] {standard_task_runner.py:57} INFO - Started process 14706 to run task
[2025-09-05T10:30:32.877-0500] {standard_task_runner.py:84} INFO - Running: ['airflow', 'tasks', 'run', 'movie_sentiment_retrain', 'check_drift', 'manual__2025-09-05T15:25:18.269925+00:00', '--job-id', '22', '--raw', '--subdir', 'DAGS_FOLDER/retrain_pipeline.py', '--cfg-path', '/var/folders/q5/0d_dg10s4m55__wc3fybh0280000gr/T/tmpz34bad8s']
[2025-09-05T10:30:32.878-0500] {standard_task_runner.py:85} INFO - Job 22: Subtask check_drift
[2025-09-05T10:30:32.896-0500] {task_command.py:416} INFO - Running <TaskInstance: movie_sentiment_retrain.check_drift manual__2025-09-05T15:25:18.269925+00:00 [running]> on host SebastianSamay.local
[2025-09-05T10:30:32.917-0500] {taskinstance.py:1662} INFO - Exporting env vars: AIRFLOW_CTX_DAG_OWNER='mlops-team' AIRFLOW_CTX_DAG_ID='movie_sentiment_retrain' AIRFLOW_CTX_TASK_ID='check_drift' AIRFLOW_CTX_EXECUTION_DATE='2025-09-05T15:25:18.269925+00:00' AIRFLOW_CTX_TRY_NUMBER='2' AIRFLOW_CTX_DAG_RUN_ID='manual__2025-09-05T15:25:18.269925+00:00'
[2025-09-05T10:30:32.921-0500] {logging_mixin.py:154} INFO - ==================================================
[2025-09-05T10:30:32.921-0500] {logging_mixin.py:154} INFO - VERIFICACIÃ“N DE DRIFT
[2025-09-05T10:30:32.922-0500] {logging_mixin.py:154} INFO - ==================================================
[2025-09-05T10:30:32.922-0500] {logging_mixin.py:154} INFO - Proyecto en: /app
[2025-09-05T10:30:32.922-0500] {logging_mixin.py:154} INFO - DRIFT_THRESHOLD: None
[2025-09-05T10:30:32.925-0500] {taskinstance.py:1937} ERROR - Task failed with exception
Traceback (most recent call last):
  File "/Users/sebatiancarvalho/Desktop/Repositorios/SCSProjects/movie-sentiment-mlops-V3/venv_mlops/lib/python3.9/site-packages/airflow/operators/python.py", line 226, in execute
    branch = super().execute(context)
  File "/Users/sebatiancarvalho/Desktop/Repositorios/SCSProjects/movie-sentiment-mlops-V3/venv_mlops/lib/python3.9/site-packages/airflow/operators/python.py", line 192, in execute
    return_value = self.execute_callable()
  File "/Users/sebatiancarvalho/Desktop/Repositorios/SCSProjects/movie-sentiment-mlops-V3/venv_mlops/lib/python3.9/site-packages/airflow/operators/python.py", line 209, in execute_callable
    return self.python_callable(*self.op_args, **self.op_kwargs)
  File "/Users/sebatiancarvalho/Desktop/Repositorios/SCSProjects/movie-sentiment-mlops-V3/airflow/dags/retrain_pipeline.py", line 64, in check_drift
    result = subprocess.run(
  File "/Library/Developer/CommandLineTools/Library/Frameworks/Python3.framework/Versions/3.9/lib/python3.9/subprocess.py", line 505, in run
    with Popen(*popenargs, **kwargs) as process:
  File "/Library/Developer/CommandLineTools/Library/Frameworks/Python3.framework/Versions/3.9/lib/python3.9/subprocess.py", line 951, in __init__
    self._execute_child(args, executable, preexec_fn, close_fds,
  File "/Library/Developer/CommandLineTools/Library/Frameworks/Python3.framework/Versions/3.9/lib/python3.9/subprocess.py", line 1821, in _execute_child
    raise child_exception_type(errno_num, err_msg, err_filename)
FileNotFoundError: [Errno 2] No such file or directory: '/app'
[2025-09-05T10:30:32.938-0500] {taskinstance.py:1400} INFO - Marking task as FAILED. dag_id=movie_sentiment_retrain, task_id=check_drift, execution_date=20250905T152518, start_date=20250905T153032, end_date=20250905T153032
[2025-09-05T10:30:32.942-0500] {standard_task_runner.py:104} ERROR - Failed to execute job 22 for task check_drift ([Errno 2] No such file or directory: '/app'; 14706)
[2025-09-05T10:30:32.971-0500] {local_task_job_runner.py:228} INFO - Task exited with return code 1
[2025-09-05T10:30:32.985-0500] {taskinstance.py:2778} INFO - 0 downstream tasks scheduled from follow-on schedule check
